[2025-08-25T15:08:09.389+0000] {local_task_job_runner.py:120} INFO - ::group::Pre task execution logs
[2025-08-25T15:08:09.820+0000] {taskinstance.py:2076} INFO - Dependencies all met for dep_context=non-requeueable deps ti=<TaskInstance: sales_data_ingestion.extract_sales_data manual__2025-08-25T15:08:07.260609+00:00 [queued]>
[2025-08-25T15:08:10.332+0000] {taskinstance.py:2076} INFO - Dependencies all met for dep_context=requeueable deps ti=<TaskInstance: sales_data_ingestion.extract_sales_data manual__2025-08-25T15:08:07.260609+00:00 [queued]>
[2025-08-25T15:08:10.333+0000] {taskinstance.py:2306} INFO - Starting attempt 1 of 1
[2025-08-25T15:08:10.351+0000] {taskinstance.py:2330} INFO - Executing <Task(PythonOperator): extract_sales_data> on 2025-08-25 15:08:07.260609+00:00
[2025-08-25T15:08:10.367+0000] {standard_task_runner.py:90} INFO - Running: ['***', 'tasks', 'run', 'sales_data_ingestion', 'extract_sales_data', 'manual__2025-08-25T15:08:07.260609+00:00', '--job-id', '2', '--raw', '--subdir', 'DAGS_FOLDER/sales_ingestion_dag.py', '--cfg-path', '/tmp/tmplnlxvbdy']
[2025-08-25T15:08:10.371+0000] {logging_mixin.py:188} WARNING - /home/***/.local/lib/python3.12/site-packages/***/task/task_runner/standard_task_runner.py:61 DeprecationWarning: This process (pid=273) is multi-threaded, use of fork() may lead to deadlocks in the child.
[2025-08-25T15:08:10.372+0000] {standard_task_runner.py:91} INFO - Job 2: Subtask extract_sales_data
[2025-08-25T15:08:10.372+0000] {standard_task_runner.py:63} INFO - Started process 275 to run task
[2025-08-25T15:08:10.432+0000] {task_command.py:426} INFO - Running <TaskInstance: sales_data_ingestion.extract_sales_data manual__2025-08-25T15:08:07.260609+00:00 [running]> on host 14dfe236c4c6
[2025-08-25T15:08:10.544+0000] {taskinstance.py:2648} INFO - Exporting env vars: AIRFLOW_CTX_DAG_OWNER='***' AIRFLOW_CTX_DAG_ID='sales_data_ingestion' AIRFLOW_CTX_TASK_ID='extract_sales_data' AIRFLOW_CTX_EXECUTION_DATE='2025-08-25T15:08:07.260609+00:00' AIRFLOW_CTX_TRY_NUMBER='1' AIRFLOW_CTX_DAG_RUN_ID='manual__2025-08-25T15:08:07.260609+00:00'
[2025-08-25T15:08:10.545+0000] {taskinstance.py:430} INFO - ::endgroup::
[2025-08-25T15:08:10.942+0000] {logging_mixin.py:188} INFO - Reading data from /opt/***/data/Orders.csv...
[2025-08-25T15:08:10.955+0000] {taskinstance.py:441} INFO - ::group::Post task execution logs
[2025-08-25T15:08:10.956+0000] {taskinstance.py:2905} ERROR - Task failed with exception
Traceback (most recent call last):
  File "/home/airflow/.local/lib/python3.12/site-packages/airflow/models/taskinstance.py", line 465, in _execute_task
    result = _execute_callable(context=context, **execute_callable_kwargs)
             ^^^^^^^^^^^^^^^^^^^^^^^^^^^^^^^^^^^^^^^^^^^^^^^^^^^^^^^^^^^^^
  File "/home/airflow/.local/lib/python3.12/site-packages/airflow/models/taskinstance.py", line 432, in _execute_callable
    return execute_callable(context=context, **execute_callable_kwargs)
           ^^^^^^^^^^^^^^^^^^^^^^^^^^^^^^^^^^^^^^^^^^^^^^^^^^^^^^^^^^^^
  File "/home/airflow/.local/lib/python3.12/site-packages/airflow/models/baseoperator.py", line 401, in wrapper
    return func(self, *args, **kwargs)
           ^^^^^^^^^^^^^^^^^^^^^^^^^^^
  File "/home/airflow/.local/lib/python3.12/site-packages/airflow/operators/python.py", line 235, in execute
    return_value = self.execute_callable()
                   ^^^^^^^^^^^^^^^^^^^^^^^
  File "/home/airflow/.local/lib/python3.12/site-packages/airflow/operators/python.py", line 252, in execute_callable
    return self.python_callable(*self.op_args, **self.op_kwargs)
           ^^^^^^^^^^^^^^^^^^^^^^^^^^^^^^^^^^^^^^^^^^^^^^^^^^^^^
  File "/opt/airflow/dags/sales_ingestion_dag.py", line 22, in _read_sales_data
    df = pd.read_csv(file_path, encoding='Windows-1252')  # Using a specific encoding for this dataset
         ^^^^^^^^^^^^^^^^^^^^^^^^^^^^^^^^^^^^^^^^^^^^^^^
  File "/home/airflow/.local/lib/python3.12/site-packages/pandas/io/parsers/readers.py", line 948, in read_csv
    return _read(filepath_or_buffer, kwds)
           ^^^^^^^^^^^^^^^^^^^^^^^^^^^^^^^
  File "/home/airflow/.local/lib/python3.12/site-packages/pandas/io/parsers/readers.py", line 611, in _read
    parser = TextFileReader(filepath_or_buffer, **kwds)
             ^^^^^^^^^^^^^^^^^^^^^^^^^^^^^^^^^^^^^^^^^^
  File "/home/airflow/.local/lib/python3.12/site-packages/pandas/io/parsers/readers.py", line 1448, in __init__
    self._engine = self._make_engine(f, self.engine)
                   ^^^^^^^^^^^^^^^^^^^^^^^^^^^^^^^^^
  File "/home/airflow/.local/lib/python3.12/site-packages/pandas/io/parsers/readers.py", line 1723, in _make_engine
    return mapping[engine](f, **self.options)
           ^^^^^^^^^^^^^^^^^^^^^^^^^^^^^^^^^^
  File "/home/airflow/.local/lib/python3.12/site-packages/pandas/io/parsers/c_parser_wrapper.py", line 93, in __init__
    self._reader = parsers.TextReader(src, **kwds)
                   ^^^^^^^^^^^^^^^^^^^^^^^^^^^^^^^
  File "parsers.pyx", line 579, in pandas._libs.parsers.TextReader.__cinit__
  File "parsers.pyx", line 668, in pandas._libs.parsers.TextReader._get_header
  File "parsers.pyx", line 879, in pandas._libs.parsers.TextReader._tokenize_rows
  File "parsers.pyx", line 890, in pandas._libs.parsers.TextReader._check_tokenize_status
  File "parsers.pyx", line 2050, in pandas._libs.parsers.raise_parser_error
  File "/usr/local/lib/python3.12/encodings/cp1252.py", line 23, in decode
    return codecs.charmap_decode(input,self.errors,decoding_table)[0]
           ^^^^^^^^^^^^^^^^^^^^^^^^^^^^^^^^^^^^^^^^^^^^^^^^^^^^^^^
UnicodeDecodeError: 'charmap' codec can't decode byte 0x9d in position 37745: character maps to <undefined>
[2025-08-25T15:08:10.972+0000] {taskinstance.py:1206} INFO - Marking task as FAILED. dag_id=sales_data_ingestion, task_id=extract_sales_data, run_id=manual__2025-08-25T15:08:07.260609+00:00, execution_date=20250825T150807, start_date=20250825T150809, end_date=20250825T150810
[2025-08-25T15:08:10.989+0000] {standard_task_runner.py:110} ERROR - Failed to execute job 2 for task extract_sales_data ('charmap' codec can't decode byte 0x9d in position 37745: character maps to <undefined>; 275)
[2025-08-25T15:08:11.028+0000] {local_task_job_runner.py:240} INFO - Task exited with return code 1
[2025-08-25T15:08:11.048+0000] {taskinstance.py:3503} INFO - 0 downstream tasks scheduled from follow-on schedule check
[2025-08-25T15:08:11.054+0000] {local_task_job_runner.py:222} INFO - ::endgroup::
